Workbook

Sheet Purchase Reciept
A2: LIVONIA TRADER - RECIEPT
B4: Item | D4: Sales | E4: Total Value | O4: Total
E5: 1
E6: 1
E7: 1 | H7: Chest 1 | I7: Chest 2 | J7: Chest 3 | K7: Chest 4 | L7: Chest 5 | M7: Chest 6 | N7: Chest 7
B8: Bear Pelt | C8: - X | D8: =SUM(H8:N8) -> 0 | E8: =VLOOKUP(B8,'Trader Prices - Public'!C:E,3,FALSE)*D8 -> 0 | O8: =SUM(H8:N8) -> 0 | S8: {=_xlfn._xlws.FILTER(B8:E32,D8:D32>0)} -> Hare Pelt | T8: - X | U8: 6 | V8: 39600
B9: Worn Bear Pelt | C9: - X | D9: =SUM(H9:N9) -> 0 | E9: =VLOOKUP(B9,'Trader Prices - Public'!C:E,3,FALSE)*D9 -> 0 | O9: =SUM(H9:N9) -> 0 | S9: Bud | T9: - X | U9: 22 | V9: 11000
B10: Reinder Pelt | C10: - X | D10: =SUM(H10:N10) -> 0 | E10: =VLOOKUP(B10,'Trader Prices - Public'!C:E,3,FALSE)*D10 -> 0 | O10: =SUM(H10:N10) -> 0 | S10: Bible | T10: - X | U10: 1 | V10: 6000
B11: Worn Reindeer Pelt | C11: - X | D11: =SUM(H11:N11) -> 0 | E11: =VLOOKUP(B11,'Trader Prices - Public'!C:E,3,FALSE)*D11 -> 0 | O11: =SUM(H11:N11) -> 0 | S11: Cigarettes | T11: - X | U11: 12 | V11: 12000
B12: Deer Pelt | C12: - X | D12: =SUM(H12:N12) -> 0 | E12: =VLOOKUP(B12,'Trader Prices - Public'!C:E,3,FALSE)*D12 -> 0 | O12: =SUM(H12:N12) -> 0 | S12: - | T12: - | U12: TOTAL: | V12: 68600
B13: Worn Deer Pelt Pelt | C13: - X | D13: =SUM(H13:N13) -> 0 | E13: =VLOOKUP(B13,'Trader Prices - Public'!C:E,3,FALSE)*D13 -> 0 | O13: =SUM(H13:N13) -> 0 | S13: - | T13: - | U13: 3 Way Split | V13: 22866.667
B14: Hare Pelt | C14: - X | D14: =SUM(H14:N14) -> 6 | E14: =VLOOKUP(B14,'Trader Prices - Public'!C:E,3,FALSE)*D14 -> 39600 | H14: 6 | O14: =SUM(H14:N14) -> 6
B15: Worn Hare Pelt | C15: - X | D15: =SUM(H15:N15) -> 0 | E15: =VLOOKUP(B15,'Trader Prices - Public'!C:E,3,FALSE)*D15 -> 0 | O15: =SUM(H15:N15) -> 0
B16: Leather Full Stack | C16: - X | D16: =SUM(H16:N16) -> 0 | E16: =VLOOKUP(B16,'Trader Prices - Public'!C:E,3,FALSE)*D16 -> 0 | O16: =SUM(H16:N16) -> 0
B17: Bud | C17: - X | D17: =SUM(H17:N17) -> 22 | E17: =VLOOKUP(B17,'Trader Prices - Public'!C:E,3,FALSE)*D17 -> 11000 | H17: 22 | O17: =SUM(H17:N17) -> 22
B18: PRG WarHead | C18: - X | D18: =SUM(H18:N18) -> 0 | E18: =VLOOKUP(B18,'Trader Prices - Public'!C:E,3,FALSE)*D18 -> 0 | O18: =SUM(H18:N18) -> 0
B19: Motor Oil | C19: - X | D19: =SUM(H19:N19) -> 0 | E19: =VLOOKUP(B19,'Trader Prices - Public'!C:E,3,FALSE)*D19 -> 0 | O19: =SUM(H19:N19) -> 0
B20: Break Fluid | C20: - X | D20: =SUM(H20:N20) -> 0 | E20: =VLOOKUP(B20,'Trader Prices - Public'!C:E,3,FALSE)*D20 -> 0 | O20: =SUM(H20:N20) -> 0
B21: Mess Tin | C21: - X | D21: =SUM(H21:N21) -> 0 | E21: =VLOOKUP(B21,'Trader Prices - Public'!C:E,3,FALSE)*D21 -> 0 | O21: =SUM(H21:N21) -> 0
B22: Butane Can | C22: - X | D22: =SUM(H22:N22) -> 0 | E22: =VLOOKUP(B22,'Trader Prices - Public'!C:E,3,FALSE)*D22 -> 0 | O22: =SUM(H22:N22) -> 0
B23: Radio | C23: - X | D23: =SUM(H23:N23) -> 0 | E23: =VLOOKUP(B23,'Trader Prices - Public'!C:E,3,FALSE)*D23 -> 0 | O23: =SUM(H23:N23) -> 0
B24: Spray Can | C24: - X | D24: =SUM(H24:N24) -> 0 | E24: =VLOOKUP(B24,'Trader Prices - Public'!C:E,3,FALSE)*D24 -> 0 | O24: =SUM(H24:N24) -> 0
B25: Cassette | C25: - X | D25: =SUM(H25:N25) -> 0 | E25: =VLOOKUP(B25,'Trader Prices - Public'!C:E,3,FALSE)*D25 -> 0 | O25: =SUM(H25:N25) -> 0
B26: Call of the Wild | C26: - X | D26: =SUM(H26:N26) -> 0 | E26: =VLOOKUP(B26,'Trader Prices - Public'!C:E,3,FALSE)*D26 -> 0 | O26: =SUM(H26:N26) -> 0
B27: Bible | C27: - X | D27: =SUM(H27:N27) -> 1 | E27: =VLOOKUP(B27,'Trader Prices - Public'!C:E,3,FALSE)*D27 -> 6000 | H27: 1 | O27: =SUM(H27:N27) -> 1
B28: Cigarettes | C28: - X | D28: =SUM(H28:N28) -> 12 | E28: =VLOOKUP(B28,'Trader Prices - Public'!C:E,3,FALSE)*D28 -> 12000 | H28: 12 | O28: =SUM(H28:N28) -> 12
C29: - X | D29: 0 | O29: =SUM(H29:N29) -> 0
D30: 0
B31: - | C31: - | D31: TOTAL: | E31: =SUM(E8:E30) -> 68600 | G31: Split | H31: 3
B32: - | C32: - | D32: =IF(H31="","",H31&" Way Split") -> 3 Way Split | E32: =IF(H31="","",E31/H31) -> 22866.667
B34: =TODAY() -> 46121

Sheet Gun Sales
B15: 100000 | D15: =TODAY() -> 46121

Sheet Trader Prices - Public
B2: WE BUY!
C4: We Buy: | E4: Price | G4: We Buy: | I4: Price | S4: 45986 | T4: 45992 | U4: 45999
C5: Bear Pelt | D5: - | E5: 55000 | G5: PRG WarHead | H5: - | I5: 10000 | J5: *All Infected | T5: 3600 | U5: 3600
C6: Worn Bear Pelt | D6: - | E6: 37500 | G6: Motor Oil | H6: - | I6: 34000 | T6: 3000 | U6: 3000
C7: Reinder Pelt | D7: - | E7: 35000 | G7: Break Fluid | H7: - | I7: 20000 | J7: * Towns / villages / Police | T7: 10800 | U7: 10800
C8: Worn Reindeer Pelt | D8: - | E8: 25000 | G8: Mess Tin | H8: - | I8: 18000 | J8: * Tier 3 Military | T8: 9000 | U8: 9000
C9: Deer Pelt | D9: - | E9: 16800 | G9: Butane Can | H9: - | I9: 15000 | J9: * Industrial sites / Farms | T9: 18600 | U9: 18600
C10: Worn Deer Pelt Pelt | D10: - | E10: 14000 | G10: Radio | H10: - | I10: 9000 | J10: * Hunting locations and on hunter zombies | T10: 15500 | U10: 15500
C11: Hare Pelt | D11: - | E11: 6600 | G11: Spray Can | H11: - | I11: 9000 | J11: * Priest Zombies / churches and the Prison | T11: 8000 | U11: 8000
C12: Worn Hare Pelt | D12: - | E12: 5500 | G12: Cassette | H12: - | I12: 3000 | J12: * Tier 3 Military | T12: 1000 | U12: 1000
C13: Leather Full Stack | D13: - | E13: 12000 | G13: Call of the Wild | H13: - | I13: 7000 | J13: * Poilice Incidents | T13: 7000 | U13: 7000
C14: Bud | D14: - | E14: 500 | G14: Bible | H14: - | I14: 6000 | J14: * HeliCrashes / Convoys | T14: 500 | U14: 500
C15: PRG WarHead | D15: - | E15: 10000 | G15: Cigarettes | H15: - | I15: 1000 | J15: * Tier 3 Military / Police locations | T15: 2500 | U15: 2500
C16: Motor Oil | D16: - | E16: 34000 | T16: 35000 | U16: 35000
C17: Break Fluid | D17: - | E17: 20000 | G17: Rival Faction Flags - $1,500,000 | T17: 13500 | U17: 13500
C18: Mess Tin | D18: - | E18: 18000 | G18: *Payment made in base upgrade vouchers, not cash | T18: 11000 | U18: 11000
C19: Butane Can | D19: - | E19: 15000 | G19: *Must be acquired through raiding | T19: 6000 | U19: 6000
C20: Radio | D20: - | E20: 9000
C21: Spray Can | D21: - | E21: 9000
C22: Cassette | D22: - | E22: 3000
C23: Call of the Wild | D23: - | E23: 7000
C24: Bible | D24: - | E24: 6000
C25: Cigarettes | D25: - | E25: 1000

Sheet Care Packages
D4: 1 person | H4: Wipe Date | M4: Wipe Date | R4: Wipe Date
D5: 1 week | H5: 2 weeks time | I5: 4 weeks time | M5: 2 weeks time | N5: 4 weeks time | R5: 2 weeks time | S5: 4 weeks time
B6: North | C6: Baked Beans x4 | D6: 10000 | F6: North | G6: Baked Beans x4 | H6: =D6*2 -> 20000 | I6: =D6*4 -> 40000 | K6: North | L6: Baked Beans x4 | M6: =D6*2*2 -> 40000 | N6: =D6*2*4 -> 80000 | P6: North | Q6: Baked Beans x4 | R6: =D6*3*2 -> 60000 | S6: =D6*3*4 -> 120000
B7: North | C7: Kitchen Knife x2 | D7: =D6+5000 -> 15000 | F7: North | G7: Kitchen Knife x2 | H7: =D7*2 -> 30000 | I7: =D7*4 -> 60000 | K7: North | L7: Kitchen Knife x2 | M7: =D7*2*2 -> 60000 | N7: =D7*2*4 -> 120000 | P7: North | Q7: Kitchen Knife x2 | R7: =D7*3*2 -> 90000 | S7: =D7*3*4 -> 180000
B8: North | C8: Map / Compass | D8: =D7+5000 -> 20000 | F8: North | G8: Map / Compass | H8: =D8*2 -> 40000 | I8: =D8*4 -> 80000 | K8: North | L8: Map / Compass | M8: =D8*2*2 -> 80000 | N8: =D8*2*4 -> 160000 | P8: North | Q8: Map / Compass | R8: =D8*3*2 -> 120000 | S8: =D8*3*4 -> 240000
B9: Trader | C9: Electrical Repair kit | D9: =D8+5000 -> 25000 | F9: Trader | G9: Electrical Repair kit | H9: =D9*2 -> 50000 | I9: =D9*4 -> 100000 | K9: Trader | L9: Electrical Repair kit | M9: =D9*2*2 -> 100000 | N9: =D9*2*4 -> 200000 | P9: Trader | Q9: Electrical Repair kit | R9: =D9*3*2 -> 150000 | S9: =D9*3*4 -> 300000
B10: North | C10: Binoculars | D10: =D9+5000 -> 30000 | F10: North | G10: Binoculars | H10: =D10*2 -> 60000 | I10: =D10*4 -> 120000 | K10: North | L10: Binoculars | M10: =D10*2*2 -> 120000 | N10: =D10*2*4 -> 240000 | P10: North | Q10: Binoculars | R10: =D10*3*2 -> 180000 | S10: =D10*3*4 -> 360000
B11: Trader | C11: Fishing Rod + military Shovel + Cooking Pot | D11: =D10+5000 -> 35000 | F11: Trader | G11: Fishing Rod + military Shovel + Cooking Pot | H11: =D11*2 -> 70000 | I11: =D11*4 -> 140000 | K11: Trader | L11: Fishing Rod + military Shovel + Cooking Pot | M11: =D11*2*2 -> 140000 | N11: =D11*2*4 -> 280000 | P11: Trader | Q11: Fishing Rod + military Shovel + Cooking Pot | R11: =D11*3*2 -> 210000 | S11: =D11*3*4 -> 420000
B12: North | C12: Trail Boots x2 | D12: =D11+5000 -> 40000 | F12: North | G12: Trail Boots x2 | H12: =D12*2 -> 80000 | I12: =D12*4 -> 160000 | K12: North | L12: Trail Boots x2 | M12: =D12*2*2 -> 160000 | N12: =D12*2*4 -> 320000 | P12: North | Q12: Trail Boots x2 | R12: =D12*3*2 -> 240000 | S12: =D12*3*4 -> 480000
B13: Trader | C13: Hiking Backpack | D13: =D12+5000 -> 45000 | F13: Trader | G13: Hiking Backpack | H13: =D13*2 -> 90000 | I13: =D13*4 -> 180000 | K13: Trader | L13: Hiking Backpack | M13: =D13*2*2 -> 180000 | N13: =D13*2*4 -> 360000 | P13: Trader | Q13: Hiking Backpack | R13: =D13*3*2 -> 270000 | S13: =D13*3*4 -> 540000
B14: Trader | C14: Bizon x2 + Mags | D14: =D13+5000 -> 50000 | F14: Trader | G14: Bizon x2 + Mags | H14: =D14*2 -> 100000 | I14: =D14*4 -> 200000 | K14: Trader | L14: Bizon x2 + Mags | M14: =D14*2*2 -> 200000 | N14: =D14*2*4 -> 400000 | P14: Trader | Q14: Bizon x2 + Mags | R14: =D14*3*2 -> 300000 | S14: =D14*3*4 -> 600000
B15: Trader | C15: Head Torch x2 | D15: =D14+5000 -> 55000 | F15: Trader | G15: Head Torch x2 | H15: =D15*2 -> 110000 | I15: =D15*4 -> 220000 | K15: Trader | L15: Head Torch x2 | M15: =D15*2*2 -> 220000 | N15: =D15*2*4 -> 440000 | P15: Trader | Q15: Head Torch x2 | R15: =D15*3*2 -> 330000 | S15: =D15*3*4 -> 660000
B16: Trader | C16: Leather Kit + Sewing Kit | D16: =D15+5000 -> 60000 | F16: Trader | G16: Leather Kit + Sewing Kit | H16: =D16*2 -> 120000 | I16: =D16*4 -> 240000 | K16: Trader | L16: Leather Kit + Sewing Kit | M16: =D16*2*2 -> 240000 | N16: =D16*2*4 -> 480000 | P16: Trader | Q16: Leather Kit + Sewing Kit | R16: =D16*3*2 -> 360000 | S16: =D16*3*4 -> 720000
B17: North | C17: Bandages x4 | D17: =D16+5000 -> 65000 | F17: North | G17: Bandages x4 | H17: =D17*2 -> 130000 | I17: =D17*4 -> 260000 | K17: North | L17: Bandages x4 | M17: =D17*2*2 -> 260000 | N17: =D17*2*4 -> 520000 | P17: North | Q17: Bandages x4 | R17: =D17*3*2 -> 390000 | S17: =D17*3*4 -> 780000
B18: Trader | C18: 1/2 stack seeds + Garden Lime | D18: =D17+5000 -> 70000 | F18: Trader | G18: 1/2 Stack Weed Seeds + Garden Lime | H18: =D18*2 -> 140000 | I18: =D18*4 -> 280000 | K18: Trader | L18: 1/2 Stack Weed Seeds + Garden Lime | M18: =D18*2*2 -> 280000 | N18: =D18*2*4 -> 560000 | P18: Trader | Q18: 1/2 Stack Weed Seeds + Garden Lime | R18: =D18*3*2 -> 420000 | S18: =D18*3*4 -> 840000
... B24: North | C24: Fishing Rod + 1 hook | D24: =D23+5000 -> 100000 | F24: North | G24: Fishing Rod + 1 hook | H24: =D24*2 -> 200000 | I24: =D24*4 -> 400000 | K24: North | L24: Fishing Rod + 1 hook | M24: =D24*2*2 -> 400000 | N24: =D24*2*4 -> 800000 | P24: North | Q24: Fishing Rod + 1 hook | R24: =D24*3*2 -> 600000 | S24: =D24*3*4 -> 1200000
H25: Total $ Earned | M25: Total $ Earned | R25: Total $ Earned
F26: YOU GET EVERYTHING UP TO YOUR TOTAL EARNED | L26: YOU GET EVERYTHING UP TO YOUR TOTAL EARNED | Q26: YOU GET EVERYTHING UP TO YOUR TOTAL EARNED

Sheet Economy
B1: Inventory slot price | C1: 500
K2: Zds | M2: Locations
C3: slots | D3: Base Price | E3: Rarity | F3: Effort | G3: Base Price | H3: Demand | I3: Price | J3: Pristine Bonus | K3: All Zombies | L3: Specific Zombies | M3: Towns | N3: Villages | O3: Farm | P3: Hunting | Q3: Industrial | R3: Police | S3: Military | T3: Prison | U3: Bunker
B4: Pristine Hare Pelt | I4: =MROUND(I5*1.2,100) -> 6600
B5: Hare Pelt | C5: 6 | D5: =$C$1*C5 -> 3000 | E5: 1.5 | F5: 0.7 | G5: =SUM(ROUND(D5*E5,0))*F5 -> 3150 | H5: 1.8 | I5: =MROUND(G5*H5,500) -> 5500
B6: Pristine Deer Pelt | I6: =MROUND(I7*1.2,100) -> 16800
B7: Deer Pelt | C7: 18 | D7: =$C$1*C7 -> 9000 | E7: 1.5 | F7: 1.3 | G7: =SUM(ROUND(D7*E7,0))*F7 -> 17550 | H7: 0.8 | I7: =MROUND(G7*H7,500) -> 14000
B8: Pristine Bear Pelt | I8: =MROUND(I9*1.2,100) -> 45000
B9: Bear Pelt | C9: 32 | D9: =$C$1*C9 -> 16000 | E9: 1.5 | F9: 1.3 | G9: =SUM(ROUND(D9*E9,0))*F9 -> 31200 | H9: 1.2 | I9: =MROUND(G9*H9,500) -> 37500
B10: Leather Full Stack | C10: 12 | D10: =$C$1*C10 -> 6000 | E10: 1 | F10: 1.3 | G10: =SUM(ROUND(D10*E10,0))*F10 -> 7800 | H10: 1.55 | I10: =MROUND(G10*H10,500) -> 12000
B11: Cigarettes | C11: 1 | D11: =$C$1*C11 -> 500 | E11: 1.5 | F11: 1 | G11: =SUM(ROUND(D11*E11,0))*F11 -> 750 | H11: 1.5 | I11: =MROUND(G11*H11,500) -> 1000 | L11: x | M11: x | N11: x | O11: x | Q11: x | R11: x | S11: x
B12: Radio | C12: 6 | D12: =$C$1*C12 -> 3000 | E12: 1.5 | F12: 1 | G12: =SUM(ROUND(D12*E12,0))*F12 -> 4500 | H12: 2 | I12: =MROUND(G12*H12,500) -> 9000 | M12: x | N12: x | O12: x | Q12: x | R12: x | S12: x
B13: Bud | C13: 1 | D13: =$C$1*C13 -> 500 | E13: 1 | F13: 1.5 | G13: =SUM(ROUND(D13*E13,0))*F13 -> 750 | H13: 1 | I13: =MROUND(G13*H13,250) -> 750 | N13: x | O13: x | P13: x
B14: Cassette | C14: 1 | D14: =$C$1*C14 -> 500 | E14: 1.5 | F14: 1 | G14: =SUM(ROUND(D14*E14,0))*F14 -> 750 | H14: 4 | I14: =MROUND(G14*H14,500) -> 3000 | M14: x | N14: x | R14: x
B15: Mess Tin | C15: 12 | D15: =$C$1*C15 -> 6000 | E15: 1.5 | F15: 1.3 | G15: =SUM(ROUND(D15*E15,0))*F15 -> 11700 | H15: 1 | I15: 24000 | S15: x
B16: Spray can | C16: 6 | D16: =$C$1*C16 -> 3000 | E16: 1.5 | F16: 1 | G16: =SUM(ROUND(D16*E16,0))*F16 -> 4500 | H16: 1.5 | I16: =MROUND(G16*H16,500) -> 7000 | M16: x | N16: x | O16: x | Q16: x
B17: Call of the wild | C17: 4 | D17: =$C$1*C17 -> 2000 | E17: 1.8 | F17: 1 | G17: =SUM(ROUND(D17*E17,0))*F17 -> 3600 | H17: 2 | I17: =MROUND(G17*H17,500) -> 7000 | L17: x | P17: x
B18: Bible | C18: 4 | D18: =$C$1*C18 -> 2000 | E18: 1.5 | F18: 1 | G18: =SUM(ROUND(D18*E18,0))*F18 -> 3000 | H18: 2 | I18: =MROUND(G18*H18,500) -> 6000 | L18: x | T18: x
B19: RPG Warhead | C19: 2 | D19: =$C$1*C19 -> 1000 | E19: 1.5 | F19: 2 | G19: =SUM(ROUND(D19*E19,0))*F19 -> 3000 | H19: 3 | I19: =MROUND(G19*H19,500) -> 9000
B20: Break Fluid | C20: 2 | D20: =$C$1*C20 -> 1000 | E20: 1.5 | F20: 2 | G20: =SUM(ROUND(D20*E20,0))*F20 -> 3000 | H20: 2 | I20: =MROUND(G20*H20,500) -> 6000
B21: Motor Oil | C21: 12 | D21: =$C$1*C21 -> 6000 | E21: 1 | F21: 4 | G21: =SUM(ROUND(D21*E21,0))*F21 -> 24000 | H21: 1.5 | I21: =MROUND(G21*H21,500) -> 36000
B22: Butane Gas | C22: 6 | D22: =$C$1*C22 -> 3000 | E22: 1 | F22: 2 | G22: =SUM(ROUND(D22*E22,0))*F22 -> 6000 | H22: 1.5 | I22: =MROUND(G22*H22,500) -> 9000
B30: Cigarettes | C30: Radio | D30: Bud | E30: Cassette | F30: Books | K30: Mess Tin | L30: Pens | M30: Spray can
X31: <tag name="shelves"/> | Y31: <usage name="Military"/> | Z31: <value name="Tier2"/> | AA31: <category name="weapons"/>
B32: <tag name="shelves"/> | C32: <tag name="shelves"/> | X32: <tag name="floor"/> | Y32: <usage name="Police"/> | Z32: <value name="Tier3"/> | AA32: <category name="food"/>
B33: <usage name="Military"/> | Y33: <usage name="Underground"/> | Z33: <value name="Unique"/> | AA33: <category name="clothes"/>
B34: <usage name="Police"/> | Y34: <usagename="Medic"/> | AA34: <category name="containers"/>
B35: <usage name="Industrial"/> | Y35: <usage name="Firefighter"/> | AA35: <category name="Explosives"/>
B36: <usage name="Town"/> | Y36: <usage name="Industrial"/> | AA36: <category name="lootdispatch"/>
B37: <usage name="Village"/> | Y37: <usage name="Town"/>
B38: <usage name="Farm"/> | Y38: <usage name="Village"/>
Y39: <usage name="Office"/>
Y40: <usage name="School"/>
Y41: <usage name="Hunting"/>
B42: <value name="Tier2"/> | Y42: <usage name="Prison"/>
B43: <value name="Tier3"/> | Y43: <usage name="Farm"/>
Y44: <usage name="SeasonalEvent"/>
Y45: <usage name="Lunapark"/>
B47: <type name="Pen_Black">
B48: <type name="Pen_Blue">
...

Sheet Trader Prices - Sell
A1: We Sell!
B3: Base Supplies | D3: Price | F3: Assault Rifels | H3: Price
B4: Combination Lock | C4: - | D4: 300000 | F4: LAR | G4: - | H4: 900000
B5: Box of nails | C5: - | D5: 100000 | F5: AUR-AX | G5: - | H5: 700000
F6: M4-A1 | G6: - | H6: 700000
B7: Sniper Rifels | D7: Price | F7: KAM | G7: - | H7: 600000
B8: DMR | C8: - | D8: 700000 | F8: S-VAL | G8: - | H8: 600000
B9: VSD | C9: - | D9: 700000 | F9: VSS | G9: - | H9: 500000
B10: CR-550 Savanna | C10: - | D10: 500000 | F10: KA-101 | G10: - | H10: 300000
B11: PIONEER | C11: - | D11: 450000 | F11: M16-A2 | G11: - | H11: 300000
B12: VS-89 | C12: - | D12: 400000 | F12: AUR-A1 | G12: - | H12: 250000
B13: TUNDRA | C13: - | D13: 350000 | F13: KA-74 | G13: - | H13: 150000
B14: BLAZE | C14: - | D14: 250000 | F14: VIKHR | G14: - | H14: 150000
B15: CR-527 | C15: - | D15: 250000

Sheet Sheet1
B15: Contract reward | D15: =TODAY() -> 46121

Sheet Sheet2
B2: Loot Pool
B4: Item | C4: Map Area | D4: Infected
B5: Wire | C5: T3
B6: Pliers | C6: T3
B7: Barbed Wire | C7: T3
B8: Pox antidote | C8: Bunker | D8: NBC / Paramedic
B9: Nails | C9: Trader
B10: Combination Locks | C10: Trader
B11: Sheet Steel | C11: T2
B12: Barrels | C12: T2
B13: Radiator | C13: T3
B14: Car Battery | C14: T3
B15: Spark Plug | C15: T3
B16: Glow Plug | C16: T3
B17: Blue Keys | C17: Prison | D17: Police Armoured
B18: Red Keys | C18: Prison | D18: Army Armoured
B19: Punchcard | C19: Prison | D19: Army Officer
B20: Yellow Key | D20: Convoy Officer
B21: NBC Gear | C21: T3 Medical / Prison
B24: Weapons
B25: SKS | C25: Bunker
B26: AK74U | C26: Heli Crash
B27: Vaiga | C27: Heli Crash
B28: R12 | C28: T3 - Police
B29: Mosin | C29: T3 Military
B30: UMP 45 | C30: T3 Military
B31: Sgk-5 | C31: T2 Police / Military
B32: Pump Shotgun | C32: T2 Police / Military
B33: Bizon | C33: T1 Poilice / Military

Sheet Sheet3
