Workbook

Sheet Sales Record
A2: Weekly Sales: | B2: 4 | C2: 45977 | D2: 45985
B3: Target
A4: Bear Pelts | B4: 4 | C4: 6 | D4: 4
A5: Deer Hides | B5: 20 | C5: 7 | D5: 13
A6: Weed | C6: 56 | D6: 56
A7: Cigarettes | C7: 3 | D7: 10
A17: Pristine Deer Pelt
A18: Deer Pelt
A19: Pristine Bear Pelt
A20: Bear Pelt
A21: Pristine Hare Pelt
A22: Hare Pelt
A23: Leather Full Stack
A24: Cigarettes
A25: Weed Bud
A26: Radio
A27: Cassettes
A28: Mess Tin
... A31: Book - The Bible

Sheet Purchase Record
B1: Us | C1: Branx | D1: Abyss | E1: Us | F1: Abyss | G1: Us | H1: Us | I1: Us | J1: ddotcaz | K1: Bandit | L1: Abyss | M1: Goss | N1: Us | O1: abyss | P1: Us | Q1: Abyss | R1: LoneSurvivor
B2: 45988 | C2: 45988 | D2: 45988 | E2: 45990 | F2: 45990 | G2: 45993 | H2: 45997 | I2: 45998 | J2: 46003 | K2: 46003 | L2: 46003 | M2: 46003 | N2: 46005 | O2: 46009 | P2: 46009 | Q2: 46012 | R2: 46012
A3: Pristine Hare Pelt | B3: 3 | D3: 3 | E3: 5 | F3: 3 | J3: 1 | L3: 3 | M3: 1 | N3: 2 | O3: 5 | R3: 1
A4: Hare Pelt | E4: 1
A5: Pristine Deer Pelt | B5: 4 | D5: 4 | I5: 1 | K5: 1 | M5: 3 | N5: 2 | O5: 7 | P5: 1 | Q5: 5 | R5: 1
A6: Deer Pelt | K6: 1 | M6: 2 | O6: 1 | P6: 1
A7: Pristine Bear Pelt | C7: 2 | Q7: 4
A8: Bear Pelt | N8: 3 | P8: 1
A9: Leather Full Stack | B9: 2 | C9: 1 | F9: 6 | K9: 1 | L9: 4 | O9: 1
A10: Cigarettes | B10: 6 | E10: 17 | G10: 9 | H10: 28 | I10: 9 | J10: 16 | K10: 9 | L10: 12 | N10: 24 | O10: 12 | P10: 28 | Q10: 22 | R10: 26
A11: Radio | C11: 1 | E11: 1 | G11: 1 | K11: 1 | L11: 2 | Q11: 1
A12: Bud | B12: 12 | D12: 49 | F12: 100 | I12: 111 | J12: 142 | N12: 249 | Q12: 58 | R12: 28
A13: Cassette | B13: 1 | C13: 3 | G13: 1 | H13: 2 | K13: 1 | P13: 2 | R13: 2
A14: Mess Tin | G14: 1 | I14: 1 | M14: 1 | N14: 4 | O14: 5 | Q14: 2
A15: Spray can | E15: 1 | K15: 1 | L15: 2 | P15: 1 | R15: 3
A16: Call of the wild | E16: 1 | H16: 4 | I16: 1 | J16: 3 | P16: 1
A17: Bible | B17: 4 | H17: 2 | J17: 2 | L17: 1 | Q17: 3

Sheet Trader Announcement
A1: Traded in last week
B3: Item | C3: Sales | E3: Total Value
B4: Pristine Hare Pelt | C4: X | D4: 14 | E4: =VLOOKUP(B4,Economy!B3:I19,8,FALSE())*D4 -> 92400
B5: Hare Pelt | C5: X | D5: 1 | E5: =VLOOKUP(B5,Economy!B4:I20,8,FALSE())*D5 -> 5500
B6: Pristine Deer Pelt | C6: X | D6: 8 | E6: =VLOOKUP(B6,Economy!B5:I21,8,FALSE())*D6 -> 134400
B7: Deer Pelt | C7: X | D7: 0 | E7: =VLOOKUP(B7,Economy!B6:I22,8,FALSE())*D7 -> 0
B8: Pristine Bear Pelt | C8: X | D8: 2 | E8: =VLOOKUP(B8,Economy!B7:I23,8,FALSE())*D8 -> 60000
B9: Bear Pelt | C9: X | D9: 0 | E9: =VLOOKUP(B9,Economy!B8:I24,8,FALSE())*D9 -> 0
B10: Leather Full Stack | C10: X | D10: 9 | E10: =VLOOKUP(B10,Economy!B9:I25,8,FALSE())*D10 -> 108000
B11: Cigarettes | C11: X | D11: 23 | E11: =VLOOKUP(B11,Economy!B10:I26,8,FALSE())*D11 -> 23000
B12: Radio | C12: X | D12: 2 | E12: =VLOOKUP(B12,Economy!B11:I27,8,FALSE())*D12 -> 18000
B13: Bud | C13: X | D13: 161 | E13: =VLOOKUP(B13,Economy!B12:I28,8,FALSE())*D13 -> 120750
B14: Cassette | C14: X | D14: 4 | E14: =VLOOKUP(B14,Economy!B13:I29,8,FALSE())*D14 -> 12000
B15: Mess Tin | C15: X | D15: 0 | E15: =VLOOKUP(B15,Economy!B14:I30,8,FALSE())*D15 -> 0
... B18: Bible | C18: X | D18: 4 | E18: =VLOOKUP(B18,Economy!B17:I33,8,FALSE())*D18 -> 24000

Sheet Reciept
A2: LIVONIA TRADER – RECEIPT
B4: Item | D4: Sales | E4: Total Value
B5: Pristine Hare Pelt | C5: - X | D5: 1 | E5: =VLOOKUP(B5,Economy!B3:I19,8,FALSE())*D5 -> 6600
B6: Hare Pelt | C6: - X | E6: =VLOOKUP(B6,Economy!B4:I20,8,FALSE())*D6 -> 0
B7: Pristine Deer Pelt | C7: - X | D7: 1 | E7: =VLOOKUP(B7,Economy!B5:I21,8,FALSE())*D7 -> 16800
B8: Deer Pelt | C8: - X | E8: =VLOOKUP(B8,Economy!B6:I22,8,FALSE())*D8 -> 0
B9: Pristine Bear Pelt | C9: - X | E9: =VLOOKUP(B9,Economy!B7:I23,8,FALSE())*D9 -> 0
B10: Bear Pelt | C10: - X | E10: =VLOOKUP(B10,Economy!B8:I24,8,FALSE())*D10 -> 0
B11: Leather Full Stack | C11: - X | E11: =VLOOKUP(B11,Economy!B9:I25,8,FALSE())*D11 -> 0
B12: Cigarettes | C12: - X | D12: 26 | E12: =VLOOKUP(B12,Economy!B10:I26,8,FALSE())*D12 -> 26000
B13: Radio | C13: - X | E13: =VLOOKUP(B13,Economy!B11:I27,8,FALSE())*D13 -> 0
B14: Bud | C14: - X | D14: 28 | E14: =VLOOKUP(B14,Economy!B12:I28,8,FALSE())*D14 -> 21000 | H14: 36 | I14: 14 | J14: 100 | K14: 71 | L14: 28
B15: Cassette | C15: - X | D15: 2 | E15: =VLOOKUP(B15,Economy!B13:I29,8,FALSE())*D15 -> 6000
B16: Mess Tin | C16: - X | E16: =VLOOKUP(B16,Economy!B14:I30,8,FALSE())*D16 -> 0
B17: Spray can | C17: - X | D17: 3 | E17: =VLOOKUP(B17,Economy!B15:I31,8,FALSE())*D17 -> 27000
B18: Call of the wild | C18: - X | E18: =VLOOKUP(B18,Economy!B16:I32,8,FALSE())*D18 -> 0
B19: Bible | C19: - X | E19: =VLOOKUP(B19,Economy!B17:I33,8,FALSE())*D19 -> 0 | J19: /3 | K19: /2
D20: TOTAL: | E20: =SUM(E5:E19) -> 103400 | J20: =$E$20/3 -> 34466.667 | K20: =$E$20/2 -> 51700 | L20: =$E$20/3 -> 34466.667
B22: =TODAY() -> 46012

Sheet Gun Sales
B15: 200000 | E15: =TODAY() -> 46012

Sheet Trader Prices - Buy
A1: We Buy!
B3: We Buy: | C3: Demand | D3: Price | L3: 45986 | M3: 45992 | N3: 45999
B4: Pristine Hare Pelt | C4: Low | D4: 6600 | M4: 3600 | N4: 3600
B5: Hare Pelt | C5: Low | D5: 5500 | M5: 3000 | N5: 3000
B6: Pristine Deer Pelt | C6: Low | D6: 16800 | M6: 10800 | N6: 10800
B7: Deer Pelt | C7: Low | D7: 14000 | M7: 9000 | N7: 9000
B8: Pristine Bear Pelt | C8: Low | D8: 30000 | M8: 18600 | N8: 18600
B9: Bear Pelt | C9: Low | D9: 25000 | M9: 15500 | N9: 15500
B10: Leather Full Stack | D10: 12000 | M10: 8000 | N10: 8000
B11: Cigarettes | C11: High | D11: 1000 | M11: 1000 | N11: 1000
B12: Radio | C12: High | D12: 9000 | M12: 7000 | N12: 7000
B13: Bud | C13: - | D13: 750 | M13: 500 | N13: 500
B14: Cassette | C14: High | D14: 3000 | M14: 2500 | N14: 2500
B15: Mess Tin | C15: Very High | D15: 24000 | E15: * Tier 3 Military | M15: 35000 | N15: 35000
B16: Spray can | C16: High | D16: 9000 | E16: * Industrial sites / Farms | M16: 13500 | N16: 13500
B17: Call of the wild | C17: Very High | D17: 7000 | E17: * Hunting locations and on hunter zombies | M17: 11000 | N17: 11000
B18: Bible | C18: High | D18: 6000 | E18: * Priest Zombies / churches and the Prison | M18: 6000 | N18: 6000

Sheet Trader Prices - Sell
A1: We Sell!
B3: Base Supplies | D3: Price | F3: Assault Rifels | H3: Price
B4: Combination Lock | C4: - | D4: 300000 | F4: LAR | G4: - | H4: 600000
B5: Box of nails | C5: - | D5: 100000 | F5: AUR-AX | G5: - | H5: 500000
F6: KAM | G6: - | H6: 500000
B7: Sniper Rifels | D7: Price | F7: M4-A1 | G7: - | H7: 500000
B8: CR-550 Savanna | C8: - | D8: 500000 | F8: S-VAL | G8: - | H8: 500000
B9: DMR | C9: - | D9: 500000 | F9: VSS | G9: - | H9: 400000
B10: PIONEER | C10: - | D10: 450000 | F10: KA-101 | G10: - | H10: 300000
B11: VS-89 | C11: - | D11: 400000 | F11: M16-A2 | G11: - | H11: 200000
B12: VSD | C12: - | D12: 500000 | F12: AUR-A1 | G12: - | H12: 150000
B13: TUNDRA | C13: - | D13: 350000 | F13: KA-74 | G13: - | H13: 150000
B14: BLAZE | C14: - | D14: 250000 | F14: VIKHR | G14: - | H14: 150000
B15: CR-527 | C15: - | D15: 250000

Sheet Economy
B1: Inventory slot price | C1: 500
K2: Zds | M2: Locations
C3: slots | D3: Base Price | E3: Rarity | F3: Effort | G3: Base Price | H3: Demand | I3: Price | J3: Pristine Bonus | K3: All Zombies | L3: Specific Zombies | M3: Towns | N3: Villages | O3: Farm | P3: Hunting | Q3: Industrial | R3: Police | S3: Military | T3: Prison | U3: Bunker
B4: Pristine Hare Pelt | I4: =MROUND(I5*1.2,100) -> 6600
B5: Hare Pelt | C5: 6 | D5: =$C$1*C5 -> 3000 | E5: 1.5 | F5: 0.7 | G5: =SUM(ROUND(D5*E5,0))*F5 -> 3150 | H5: 1.7 | I5: =MROUND(G5*H5,500) -> 5500
B6: Pristine Deer Pelt | I6: =MROUND(I7*1.2,100) -> 16800
B7: Deer Pelt | C7: 18 | D7: =$C$1*C7 -> 9000 | E7: 1.5 | F7: 1.3 | G7: =SUM(ROUND(D7*E7,0))*F7 -> 17550 | H7: 0.8 | I7: =MROUND(G7*H7,500) -> 14000
B8: Pristine Bear Pelt | I8: =MROUND(I9*1.2,100) -> 30000
B9: Bear Pelt | C9: 32 | D9: =$C$1*C9 -> 16000 | E9: 1.5 | F9: 1.3 | G9: =SUM(ROUND(D9*E9,0))*F9 -> 31200 | H9: 0.8 | I9: =MROUND(G9*H9,500) -> 25000
B10: Leather Full Stack | C10: 12 | D10: =$C$1*C10 -> 6000 | E10: 1 | F10: 1.3 | G10: =SUM(ROUND(D10*E10,0))*F10 -> 7800 | H10: 1.55 | I10: =MROUND(G10*H10,500) -> 12000
B11: Cigarettes | C11: 1 | D11: =$C$1*C11 -> 500 | E11: 1.5 | F11: 1 | G11: =SUM(ROUND(D11*E11,0))*F11 -> 750 | H11: 1.5 | I11: =MROUND(G11*H11,500) -> 1000 | L11: x | M11: x | N11: x | O11: x | Q11: x | R11: x | S11: x
B12: Radio | C12: 6 | D12: =$C$1*C12 -> 3000 | E12: 1.5 | F12: 1 | G12: =SUM(ROUND(D12*E12,0))*F12 -> 4500 | H12: 2 | I12: =MROUND(G12*H12,500) -> 9000 | M12: x | N12: x | O12: x | Q12: x | R12: x | S12: x
B13: Bud | C13: 1 | D13: =$C$1*C13 -> 500 | E13: 1 | F13: 1.5 | G13: =SUM(ROUND(D13*E13,0))*F13 -> 750 | H13: 1 | I13: =MROUND(G13*H13,250) -> 750 | N13: x | O13: x | P13: x
B14: Cassette | C14: 1 | D14: =$C$1*C14 -> 500 | E14: 1.5 | F14: 1 | G14: =SUM(ROUND(D14*E14,0))*F14 -> 750 | H14: 4 | I14: =MROUND(G14*H14,500) -> 3000 | M14: x | N14: x | R14: x
B15: Mess Tin | C15: 12 | D15: =$C$1*C15 -> 6000 | E15: 1.5 | F15: 1.3 | G15: =SUM(ROUND(D15*E15,0))*F15 -> 11700 | H15: 2.05 | I15: =MROUND(G15*H15,500) -> 24000 | S15: x
B16: Spray can | C16: 6 | D16: =$C$1*C16 -> 3000 | E16: 1.5 | F16: 1 | G16: =SUM(ROUND(D16*E16,0))*F16 -> 4500 | H16: 2 | I16: =MROUND(G16*H16,500) -> 9000 | M16: x | N16: x | O16: x | Q16: x
B17: Call of the wild | C17: 4 | D17: =$C$1*C17 -> 2000 | E17: 1.8 | F17: 1 | G17: =SUM(ROUND(D17*E17,0))*F17 -> 3600 | H17: 2 | I17: =MROUND(G17*H17,500) -> 7000 | L17: x | P17: x
B18: Bible | C18: 4 | D18: =$C$1*C18 -> 2000 | E18: 1.5 | F18: 1 | G18: =SUM(ROUND(D18*E18,0))*F18 -> 3000 | H18: 2 | I18: =MROUND(G18*H18,500) -> 6000 | L18: x | T18: x
B20: Cigarettes | C20: Radio | D20: Bud | E20: Cassette | F20: Books | K20: Mess Tin | L20: Pens | M20: Spray can
X21: <tag name="shelves"/> | Y21: <usage name="Military"/> | Z21: <value name="Tier2"/> | AA21: <category name="weapons"/>
B22: <tag name="shelves"/> | C22: <tag name="shelves"/> | X22: <tag name="floor"/> | Y22: <usage name="Police"/> | Z22: <value name="Tier3"/> | AA22: <category name="food"/>
B23: <usage name="Military"/> | Y23: <usage name="Underground"/> | Z23: <value name="Unique"/> | AA23: <category name="clothes"/>
B24: <usage name="Police"/> | Y24: <usagename="Medic"/> | AA24: <category name="containers"/>
B25: <usage name="Industrial"/> | Y25: <usage name="Firefighter"/> | AA25: <category name="Explosives"/>
B26: <usage name="Town"/> | Y26: <usage name="Industrial"/> | AA26: <category name="lootdispatch"/>
B27: <usage name="Village"/> | Y27: <usage name="Town"/>
B28: <usage name="Farm"/> | Y28: <usage name="Village"/>
Y29: <usage name="Office"/>
Y30: <usage name="School"/>
Y31: <usage name="Hunting"/>
B32: <value name="Tier2"/> | Y32: <usage name="Prison"/>
B33: <value name="Tier3"/> | Y33: <usage name="Farm"/>
Y34: <usage name="SeasonalEvent"/>
Y35: <usage name="Lunapark"/>
B37: <type name="Pen_Black">
B38: <type name="Pen_Blue">
B39: <type name="Pen_Green">
B40: <type name="Pen_Red">
B42: <type name="CigarettePack_Chernamorka">
B43: <type name="CigarettePack_Merkur">
...
